{"trial_id": "09", "hyperparameters": {"space": [{"class_name": "Int", "config": {"name": "conv_filters", "default": null, "conditions": [], "min_value": 16, "max_value": 64, "step": 16, "sampling": "linear"}}, {"class_name": "Choice", "config": {"name": "conv_kernel_size", "default": 3, "conditions": [], "values": [3, 5], "ordered": true}}, {"class_name": "Int", "config": {"name": "dense_units", "default": null, "conditions": [], "min_value": 128, "max_value": 256, "step": 64, "sampling": "linear"}}, {"class_name": "Float", "config": {"name": "learning_rate", "default": 0.001, "conditions": [], "min_value": 0.0001, "max_value": 0.01, "step": null, "sampling": "log"}}], "values": {"conv_filters": 64, "conv_kernel_size": 5, "dense_units": 192, "learning_rate": 0.00028546666455663456}}, "metrics": {"metrics": {}}, "score": null, "best_step": 0, "status": "FAILED", "message": "Traceback (most recent call last):\n  File \"/home/sandra/deedevelopment.ai/resmol/venv/lib/python3.10/site-packages/keras_tuner/engine/base_tuner.py\", line 270, in _try_run_and_update_trial\n    self._run_and_update_trial(trial, *fit_args, **fit_kwargs)\n  File \"/home/sandra/deedevelopment.ai/resmol/venv/lib/python3.10/site-packages/keras_tuner/engine/base_tuner.py\", line 235, in _run_and_update_trial\n    results = self.run_trial(trial, *fit_args, **fit_kwargs)\n  File \"/home/sandra/deedevelopment.ai/resmol/venv/lib/python3.10/site-packages/keras_tuner/engine/tuner.py\", line 287, in run_trial\n    obj_value = self._build_and_fit_model(trial, *args, **copied_kwargs)\n  File \"/home/sandra/deedevelopment.ai/resmol/venv/lib/python3.10/site-packages/keras_tuner/engine/tuner.py\", line 213, in _build_and_fit_model\n    model = self._try_build(hp)\n  File \"/home/sandra/deedevelopment.ai/resmol/venv/lib/python3.10/site-packages/keras_tuner/engine/tuner.py\", line 155, in _try_build\n    model = self._build_hypermodel(hp)\n  File \"/home/sandra/deedevelopment.ai/resmol/venv/lib/python3.10/site-packages/keras_tuner/engine/tuner.py\", line 146, in _build_hypermodel\n    model = self.hypermodel.build(hp)\n  File \"/tmp/ipykernel_21306/3164849795.py\", line 10, in build_model\n    conv_H_1d = Conv1D(filters=hp.Int('conv_filters', min_value=16, max_value=128, step=16),\n  File \"/home/sandra/deedevelopment.ai/resmol/venv/lib/python3.10/site-packages/keras/utils/traceback_utils.py\", line 70, in error_handler\n    raise e.with_traceback(filtered_tb) from None\n  File \"/home/sandra/deedevelopment.ai/resmol/venv/lib/python3.10/site-packages/tensorflow/python/framework/ops.py\", line 1973, in _create_c_op\n    raise ValueError(e.message)\nValueError: Exception encountered when calling layer \"conv1d_1\" (type Conv1D).\n\nNegative dimension size caused by subtracting 5 from 4 for '{{node conv1d_1/Conv1D}} = Conv2D[T=DT_FLOAT, data_format=\"NHWC\", dilations=[1, 1, 1, 1], explicit_paddings=[], padding=\"VALID\", strides=[1, 1, 1, 1], use_cudnn_on_gpu=true](conv1d_1/Conv1D/ExpandDims, conv1d_1/Conv1D/ExpandDims_1)' with input shapes: [?,1,4,1], [1,5,1,64].\n\nCall arguments received by layer \"conv1d_1\" (type Conv1D):\n  \u2022 inputs=tf.Tensor(shape=(None, 4, 1), dtype=float32)\n"}